<?xml version="1.0" ?>
<!-- =================================================================================== -->
<!-- |    This document was autogenerated by xacro from nanocarpro_description.urdf.xacro | -->
<!-- |    EDITING THIS FILE BY HAND IS NOT RECOMMENDED                                 | -->
<!-- =================================================================================== -->
<robot name="NanoCarPro">
  <gazebo reference="base_link">
    <material>Gazebo/DarkGrey</material>
  </gazebo>
  <gazebo reference="/front_left_wheel_link">
    <mu1>0.5</mu1>
    <mu2>0.5</mu2>
    <kp>500000.0</kp>
    <kd>10.0</kd>
    <minDepth>0.001</minDepth>
    <maxVel>1.0</maxVel>
    <fdir1>1 0 0</fdir1>
    <material>Gazebo/FlatBlack</material>
  </gazebo>
  <gazebo reference="/front_right_wheel_link">
    <mu1>0.5</mu1>
    <mu2>0.5</mu2>
    <kp>500000.0</kp>
    <kd>10.0</kd>
    <minDepth>0.001</minDepth>
    <maxVel>1.0</maxVel>
    <fdir1>1 0 0</fdir1>
    <material>Gazebo/FlatBlack</material>
  </gazebo>
  <gazebo reference="/back_left_wheel_link">
    <mu1>0.5</mu1>
    <mu2>0.5</mu2>
    <kp>500000.0</kp>
    <kd>10.0</kd>
    <minDepth>0.001</minDepth>
    <maxVel>1.0</maxVel>
    <fdir1>1 0 0</fdir1>
    <material>Gazebo/FlatBlack</material>
  </gazebo>
  <gazebo reference="/back_right_wheel_link">
    <mu1>0.5</mu1>
    <mu2>0.5</mu2>
    <kp>500000.0</kp>
    <kd>10.0</kd>
    <minDepth>0.001</minDepth>
    <maxVel>1.0</maxVel>
    <fdir1>1 0 0</fdir1>
    <material>Gazebo/FlatBlack</material>
  </gazebo>
  <gazebo>
    <plugin filename="libgazebo_ros_skid_steer_drive.so" name="skid_steer_drive_controller">
      <updateRate>100.0</updateRate>
      <!-- <robotNamespace>/</robotNamespace> -->
      <leftFrontJoint>front_left_wheel_joint</leftFrontJoint>
      <rightFrontJoint>front_right_wheel_joint</rightFrontJoint>
      <leftRearJoint>back_left_wheel_joint</leftRearJoint>
      <rightRearJoint>back_right_wheel_joint</rightRearJoint>
      <wheelSeparation>0.1745</wheelSeparation>
      <wheelDiameter>0.067</wheelDiameter>
      <robotBaseFrame>base_footprint</robotBaseFrame>
      <torque>20</torque>
      <commandTopic>cmd_vel</commandTopic>
      <odometryTopic>odom</odometryTopic>
      <odometryFrame>odom</odometryFrame>
      <covariance_x>0.0001</covariance_x>
      <covariance_y>0.0001</covariance_y>
      <covariance_yaw>0.0001</covariance_yaw>
      <broadcastTF>true</broadcastTF>
    </plugin>
  </gazebo>
  <gazebo reference="/imu">
    <sensor name="imu" type="imu">
      <always_on>true</always_on>
      <visualize>false</visualize>
    </sensor>
    <material>Gazebo/FlatBlack</material>
  </gazebo>
  <gazebo>
    <plugin filename="libgazebo_ros_imu.so" name="imu_plugin">
      <alwaysOn>true</alwaysOn>
      <bodyName>/imu</bodyName>
      <frameName>imu</frameName>
      <topicName>imu</topicName>
      <serviceName>imu_service</serviceName>
      <gaussianNoise>0.0</gaussianNoise>
      <updateRate>0</updateRate>
      <imu>
        <noise>
          <type>gaussian</type>
          <rate>
            <mean>0.0</mean>
            <stddev>2e-4</stddev>
            <bias_mean>0.0000075</bias_mean>
            <bias_stddev>0.0000008</bias_stddev>
          </rate>
          <accel>
            <mean>0.0</mean>
            <stddev>1.7e-2</stddev>
            <bias_mean>0.1</bias_mean>
            <bias_stddev>0.001</bias_stddev>
          </accel>
        </noise>
      </imu>
    </plugin>
  </gazebo>
  <gazebo reference="/base_laser_link">
    <material>Gazebo/FlatBlack</material>
    <sensor name="rplidar_sensor" type="ray">
      <pose>0 0 0 0 0 0</pose>
      <visualize>false</visualize>
      <update_rate>7</update_rate>
      <ray>
        <scan>
          <horizontal>
            <samples>720</samples>
            <resolution>0.5</resolution>
            <min_angle>0.0</min_angle>
            <max_angle>6.28319</max_angle>
          </horizontal>
        </scan>
        <range>
          <min>0.120</min>
          <max>12.0</max>
          <resolution>0.015</resolution>
        </range>
        <noise>
          <type>gaussian</type>
          <mean>0.0</mean>
          <stddev>0.01</stddev>
        </noise>
      </ray>
      <plugin filename="libgazebo_ros_laser.so" name="gazebo_ros_rplidar_controller">
        <topicName>scan</topicName>
        <frameName>base_laser_link</frameName>
      </plugin>
    </sensor>
  </gazebo>
  <gazebo reference="/base_camera_link">
    <sensor name="csi Camera" type="camera">
      <always_on>true</always_on>
      <visualize>false</visualize>
      <camera>
        <horizontal_fov>1.085595</horizontal_fov>
        <image>
          <width>640</width>
          <height>480</height>
          <format>R8G8B8</format>
        </image>
        <clip>
          <near>0.03</near>
          <far>100</far>
        </clip>
      </camera>
      <plugin filename="libgazebo_ros_camera.so" name="camera_controller">
        <alwaysOn>true</alwaysOn>
        <updateRate>30.0</updateRate>
        <cameraName>/</cameraName>
        <frameName>base_camera_link</frameName>
        <imageTopicName>image_raw</imageTopicName>
        <cameraInfoTopicName>camera_info</cameraInfoTopicName>
        <hackBaseline>0.07</hackBaseline>
        <distortionK1>0.0</distortionK1>
        <distortionK2>0.0</distortionK2>
        <distortionK3>0.0</distortionK3>
        <distortionT1>0.0</distortionT1>
        <distortionT2>0.0</distortionT2>
      </plugin>
    </sensor>
  </gazebo>
  <gazebo reference="/camera_link">
    <sensor name="ir Camera" type="depth">
      <update_rate>20</update_rate>
      <camera>
        <horizontal_fov>1.047198</horizontal_fov>
        <image>
          <width>640</width>
          <height>480</height>
          <format>R8G8B8</format>
        </image>
        <clip>
          <near>0.05</near>
          <far>3</far>
        </clip>
      </camera>
      <plugin filename="libgazebo_ros_openni_kinect.so" name="ir_camera_controller">
        <baseline>0.2</baseline>
        <alwaysOn>true</alwaysOn>
        <updateRate>1.0</updateRate>
        <cameraName>camera_ir</cameraName>
        <imageTopicName>//camera/color/image_raw</imageTopicName>
        <cameraInfoTopicName>//camera/color/camera_info</cameraInfoTopicName>
        <depthImageTopicName>//camera/depth/image_raw</depthImageTopicName>
        <depthImageInfoTopicName>//camera/depth/camera_info</depthImageInfoTopicName>
        <pointCloudTopicName>//camera/depth/points</pointCloudTopicName>
        <frameName>camera_link</frameName>
        <pointCloudCutoff>0.5</pointCloudCutoff>
        <pointCloudCutoffMax>3.0</pointCloudCutoffMax>
        <distortionK1>0.00000001</distortionK1>
        <distortionK2>0.00000001</distortionK2>
        <distortionK3>0.00000001</distortionK3>
        <distortionT1>0.00000001</distortionT1>
        <distortionT2>0.00000001</distortionT2>
        <CxPrime>0</CxPrime>
        <Cx>0</Cx>
        <Cy>0</Cy>
        <focalLength>0</focalLength>
        <hackBaseline>0</hackBaseline>
      </plugin>
    </sensor>
  </gazebo>
  <link name="/base_footprint"/>
  <joint name="base_joint" type="fixed">
    <parent link="/base_footprint"/>
    <child link="base_link"/>
    <origin rpy="0 0 0" xyz="0.0 0.0 0.0157"/>
  </joint>
  <link name="base_link">
    <inertial>
      <origin rpy="0 0 0" xyz="0.072991 0.00046853 0.039966"/>
      <mass value="0.45437"/>
      <inertia ixx="0.00029844" ixy="-4.3951E-06" ixz="-2.191E-06" iyy="0.00043198" iyz="3.005E-07" izz="0.00068218"/>
    </inertial>
    <visual>
      <origin rpy="0 0 0" xyz="0 0 0"/>
      <geometry>
        <mesh filename="../meshes/base_link.obj"/>
      </geometry>
      <material name="">
        <color rgba="1 1 1 1"/>
      </material>
    </visual>
    <collision>
      <origin rpy="0 0 0" xyz="0.075 0 0.0475"/>
      <geometry>
        <!-- <mesh filename="../meshes/base_link.obj"/> -->
        <box size="0.21 0.1 0.095"/>
      </geometry>
      <!-- <origin rpy="0 0 0" xyz="0 0 0"/>
      <geometry>
        <mesh filename="../meshes/base_link.obj"/>
      </geometry> -->
    </collision>
  </link>
  <link name="/front_left_wheel_link">
    <inertial>
      <origin rpy="0 0 0" xyz="-1.914E-05 -4.1633E-16 -0.0055056"/>
      <mass value="0.056134"/>
      <inertia ixx="2.4529E-05" ixy="1.012E-19" ixz="6.1905E-08" iyy="2.4528E-05" iyz="1.0409E-17" izz="4.2335E-05"/>
    </inertial>
    <visual>
      <origin rpy="0 0 0" xyz="0 0 0"/>
      <geometry>
        <mesh filename="../meshes/front_left_wheel_link.obj"/>
      </geometry>
      <material name="">
        <color rgba="0.1098 0.1098 0.1098 1"/>
      </material>
    </visual>
    <collision>
      <origin rpy="0 0 0" xyz="0 0 0"/>
      <geometry>
        <mesh filename="../meshes/front_left_wheel_link.obj"/>
      </geometry>
    </collision>
  </link>
  <joint name="front_left_wheel_joint" type="continuous">
    <!-- <origin rpy="-1.5708 0 0" xyz="0.14338 0.08725 0.0179"/> -->
    <origin rpy="0 0 0" xyz="0 0 0.03725"/>
    <parent link="/left_steering_link"/>
    <child link="/front_left_wheel_link"/>
    <axis xyz="0 0 1"/>
  </joint>
  <link name="/left_steering_link">
    <!-- <visual>
      <origin rpy="0 0 0" xyz="0 0 0"/>
      <geometry>
        <sphere radius="0.0001"/>
      </geometry>
      <material name="">
        <color rgba="0.1098 0.1098 0.1098 1"/>
      </material>
    </visual> -->
  </link>
  <joint name="left_steering_joint" type="continuous">
    <parent link="base_link"/>
    <child link="/left_steering_link"/>
    <origin rpy="-1.5708 0 0" xyz="0.14338 0.05 0.0179"/>
    <axis xyz="0 -1 0"/>
  </joint>
  
  <link name="/front_right_wheel_link">
    <inertial>
      <origin rpy="0 0 0" xyz="-1.914E-05 -4.1633E-16 -0.0055056"/>
      <mass value="0.056134"/>
      <inertia ixx="2.4529E-05" ixy="1.012E-19" ixz="6.1905E-08" iyy="2.4528E-05" iyz="1.0409E-17" izz="4.2335E-05"/>
    </inertial>
    <visual>
      <origin rpy="0 0 0" xyz="0 0 0"/>
      <geometry>
        <mesh filename="../meshes/front_right_wheel_link.obj"/>
      </geometry>
      <material name="">
        <color rgba="0.1098 0.1098 0.1098 1"/>
      </material>
    </visual>
    <collision>
      <origin rpy="0 0 0" xyz="0 0 0"/>
      <geometry>
        <mesh filename="../meshes/front_right_wheel_link.obj"/>
      </geometry>
    </collision>
  </link>
  <joint name="front_right_wheel_joint" type="continuous">
    <!-- <origin rpy="-1.5708 0 -3.1416" xyz="0.14338 -0.08725 0.0179"/> -->
    <origin rpy="0 0 0" xyz="0 0 0.03725"/>
    <parent link="/right_steering_link"/>
    <child link="/front_right_wheel_link"/>
    <axis xyz="0 0 -1"/>
  </joint>
  <link name="/right_steering_link">
    <!-- <visual>
      <origin rpy="0 0 0" xyz="0 0 0"/>
      <geometry>
        <sphere radius="0.0001"/>
      </geometry>
      <material name="">
        <color rgba="0.1098 0.1098 0.1098 1"/>
      </material>
    </visual> -->
  </link>
  <joint name="right_steering_joint" type="continuous">
    <parent link="base_link"/>
    <child link="/right_steering_link"/>
    <origin rpy="-1.5708 0 -3.1416" xyz="0.14338 -0.05 0.0179"/>
    <axis xyz="0 -1 0"/>
  </joint>
  <link name="/back_left_wheel_link">
    <inertial>
      <origin rpy="0 0 0" xyz="-1.914E-05 -4.1633E-16 -0.0055056"/>
      <mass value="0.056134"/>
      <inertia ixx="2.4529E-05" ixy="1.012E-19" ixz="6.1905E-08" iyy="2.4528E-05" iyz="1.0409E-17" izz="4.2335E-05"/>
    </inertial>
    <visual>
      <origin rpy="0 0 0" xyz="0 0 0"/>
      <geometry>
        <mesh filename="../meshes/back_left_wheel_link.obj"/>
      </geometry>
      <material name="">
        <color rgba="0.1098 0.1098 0.1098 1"/>
      </material>
    </visual>
    <collision>
      <origin rpy="0 0 0" xyz="0 0 0"/>
      <geometry>
        <mesh filename="../meshes/back_left_wheel_link.obj"/>
      </geometry>
    </collision>
  </link>
  <joint name="back_left_wheel_joint" type="continuous">
    <origin rpy="-1.5708 0 0" xyz="-0.00015 0.08725 0.0179"/>
    <parent link="base_link"/>
    <child link="/back_left_wheel_link"/>
    <axis xyz="0 0 1"/>
  </joint>
  <link name="/back_right_wheel_link">
    <inertial>
      <origin rpy="0 0 0" xyz="-1.914E-05 -4.1633E-16 -0.0055056"/>
      <mass value="0.056134"/>
      <inertia ixx="2.4529E-05" ixy="1.012E-19" ixz="6.1905E-08" iyy="2.4528E-05" iyz="1.0409E-17" izz="4.2335E-05"/>
    </inertial>
    <visual>
      <origin rpy="0 0 0" xyz="0 0 0"/>
      <geometry>
        <mesh filename="../meshes/back_right_wheel_link.obj"/>
      </geometry>
      <material name="">
        <color rgba="0.1098 0.1098 0.1098 1"/>
      </material>
    </visual>
    <collision>
      <origin rpy="0 0 0" xyz="0 0 0"/>
      <geometry>
        <mesh filename="../meshes/back_right_wheel_link.obj"/>
      </geometry>
    </collision>
  </link>
  <joint name="back_right_wheel_joint" type="continuous">
    <origin rpy="-1.5708 0 3.1416" xyz="0.00015 -0.08725 0.0179"/>
    <parent link="base_link"/>
    <child link="/back_right_wheel_link"/>
    <axis xyz="0 0 -1"/>
  </joint>
  <!-- laser -->
  <link name="/base_laser_link"/>
  <joint name="laser_joint" type="fixed">
    <origin rpy="0 0 3.1416" xyz="0.11449 0 0.141"/>
    <parent link="base_link"/>
    <child link="/base_laser_link"/>
    <axis xyz="0 0 0"/>
  </joint>
  <!-- rgb camera -->
  <link name="/base_camera_link"/>
  <joint name="camera_joint" type="fixed">
    <origin rpy="0 0 0" xyz="0.15917 0.019164 0.073"/>
    <parent link="base_link"/>
    <child link="/base_camera_link"/>
    <axis xyz="0 0 0"/>
  </joint>
  <!-- imu -->
  <link name="/imu"/>
  <joint name="imu_joint" type="fixed">
    <origin rpy="0 0 0" xyz="0.0653 -0.0275 0.07671"/>
    <parent link="base_link"/>
    <child link="/imu"/>
    <axis xyz="0 0 0"/>
  </joint>
  <!-- ir camera -->
  <link name="/camera_link"/>
  <joint name="ir_camera_joint" type="fixed">
    <origin rpy="0 0 0" xyz="0.15917 0.039164 0.073"/>
    <parent link="base_link"/>
    <child link="/camera_link"/>
    <axis xyz="0 0 0"/>
  </joint>
</robot>

