<?xml version="1.0" ?>
<!-- =================================================================================== -->
<!-- |    This document was autogenerated by xacro from nanocarpro_description.urdf.xacro | -->
<!-- |    EDITING THIS FILE BY HAND IS NOT RECOMMENDED                                 | -->
<!-- =================================================================================== -->
<robot name="NanoCarPro">
  <link name="base"/>
  <joint name="base_joint" type="fixed">
    <parent link="base"/>
    <child link="base_link"/>
    <origin rpy="0 0 0" xyz="0.0 0.0 0.0157"/>
  </joint>
  <link name="base_link">
    <inertial>
      <origin rpy="0 0 0" xyz="0.072991 0.00046853 0.039966"/>
      <mass value="0.45437"/>
      <inertia ixx="0.00029844" ixy="-4.3951E-06" ixz="-2.191E-06" iyy="0.00043198" iyz="3.005E-07" izz="0.00068218"/>
    </inertial>
    <visual>
      <origin rpy="0 0 0" xyz="0 0 0"/>
      <geometry>
        <mesh filename="../meshes/base_link.obj"/>
      </geometry>
      <material name="">
        <color rgba="1 1 1 1"/>
      </material>
    </visual>
    <collision>
      <origin rpy="0 0 0" xyz="0.075 0 0.0475"/>
      <geometry>
        <box size="0.21 0.1 0.095"/>
      </geometry>
      <!-- <origin rpy="0 0 0" xyz="0 0 0"/>
      <geometry>
        <mesh filename="../meshes/base_link.obj"/>
      </geometry> -->
    </collision>
  </link>
  <link name="/front_left_wheel_link">
    <inertial>
      <origin rpy="0 0 0" xyz="-1.914E-05 -4.1633E-16 -0.0055056"/>
      <mass value="0.056134"/>
      <inertia ixx="2.4529E-05" ixy="1.012E-19" ixz="6.1905E-08" iyy="2.4528E-05" iyz="1.0409E-17" izz="4.2335E-05"/>
    </inertial>
    <visual>
      <origin rpy="0 0 0" xyz="0 0 0"/>
      <geometry>
        <mesh filename="../meshes/front_left_wheel_link.obj"/>
      </geometry>
      <material name="">
        <color rgba="0.1098 0.1098 0.1098 1"/>
      </material>
    </visual>
    <collision>
      <origin rpy="0 0 0" xyz="0 0 0"/>
      <geometry>
        <mesh filename="../meshes/front_left_wheel_link.obj"/>
      </geometry>
    </collision>
  </link>
  <joint name="front_left_wheel_joint" type="continuous">
    <!-- <origin rpy="-1.5708 0 0" xyz="0.14338 0.08725 0.0179"/> -->
    <origin rpy="0 0 0" xyz="0 0 0.03725"/>
    <parent link="/left_steering_link"/>
    <child link="/front_left_wheel_link"/>
    <axis xyz="0 0 1"/>
  </joint>
  <link name="/left_steering_link">
    <!-- <visual>
      <origin rpy="0 0 0" xyz="0 0 0"/>
      <geometry>
        <sphere radius="0.0001"/>
      </geometry>
      <material name="">
        <color rgba="0.1098 0.1098 0.1098 1"/>
      </material>
    </visual> -->
  </link>
  <joint name="left_steering_joint" type="revolute">
    <parent link="base_link"/>
    <child link="/left_steering_link"/>
    <origin rpy="-1.5708 0 0" xyz="0.14338 0.05 0.0179"/>
    <limit effort="30" velocity="2.0" lower="-0.7854" upper="0.7854" />
    <axis xyz="0 -1 0"/>
  </joint>
  
  <link name="/front_right_wheel_link">
    <inertial>
      <origin rpy="0 0 0" xyz="-1.914E-05 -4.1633E-16 -0.0055056"/>
      <mass value="0.056134"/>
      <inertia ixx="2.4529E-05" ixy="1.012E-19" ixz="6.1905E-08" iyy="2.4528E-05" iyz="1.0409E-17" izz="4.2335E-05"/>
    </inertial>
    <visual>
      <origin rpy="0 0 0" xyz="0 0 0"/>
      <geometry>
        <mesh filename="../meshes/front_right_wheel_link.obj"/>
      </geometry>
      <material name="">
        <color rgba="0.1098 0.1098 0.1098 1"/>
      </material>
    </visual>
    <collision>
      <origin rpy="0 0 0" xyz="0 0 0"/>
      <geometry>
        <mesh filename="../meshes/front_right_wheel_link.obj"/>
      </geometry>
    </collision>
  </link>
  <joint name="front_right_wheel_joint" type="continuous">
    <!-- <origin rpy="-1.5708 0 -3.1416" xyz="0.14338 -0.08725 0.0179"/> -->
    <origin rpy="0 0 0" xyz="0 0 0.03725"/>
    <parent link="/right_steering_link"/>
    <child link="/front_right_wheel_link"/>
    <axis xyz="0 0 -1"/>
  </joint>
  <link name="/right_steering_link">
    <!-- <visual>
      <origin rpy="0 0 0" xyz="0 0 0"/>
      <geometry>
        <sphere radius="0.0001"/>
      </geometry>
      <material name="">
        <color rgba="0.1098 0.1098 0.1098 1"/>
      </material>
    </visual> -->
  </link>
  <joint name="right_steering_joint" type="revolute">
    <parent link="base_link"/>
    <child link="/right_steering_link"/>
    <origin rpy="-1.5708 0 -3.1416" xyz="0.14338 -0.05 0.0179"/>
    <limit effort="30" velocity="2.0" lower="-0.7854" upper="0.7854" />
    <axis xyz="0 -1 0"/>
  </joint>
  <link name="/back_left_wheel_link">
    <inertial>
      <origin rpy="0 0 0" xyz="-1.914E-05 -4.1633E-16 -0.0055056"/>
      <mass value="0.056134"/>
      <inertia ixx="2.4529E-05" ixy="1.012E-19" ixz="6.1905E-08" iyy="2.4528E-05" iyz="1.0409E-17" izz="4.2335E-05"/>
    </inertial>
    <visual>
      <origin rpy="0 0 0" xyz="0 0 0"/>
      <geometry>
        <mesh filename="../meshes/back_left_wheel_link.obj"/>
      </geometry>
      <material name="">
        <color rgba="0.1098 0.1098 0.1098 1"/>
      </material>
    </visual>
    <collision>
      <origin rpy="0 0 0" xyz="0 0 0"/>
      <geometry>
        <mesh filename="../meshes/back_left_wheel_link.obj"/>
      </geometry>
    </collision>
  </link>
  <joint name="back_left_wheel_joint" type="continuous">
    <origin rpy="-1.5708 0 0" xyz="-0.00015 0.08725 0.0179"/>
    <parent link="base_link"/>
    <child link="/back_left_wheel_link"/>
    <axis xyz="0 0 1"/>
  </joint>
  <link name="/back_right_wheel_link">
    <inertial>
      <origin rpy="0 0 0" xyz="-1.914E-05 -4.1633E-16 -0.0055056"/>
      <mass value="0.056134"/>
      <inertia ixx="2.4529E-05" ixy="1.012E-19" ixz="6.1905E-08" iyy="2.4528E-05" iyz="1.0409E-17" izz="4.2335E-05"/>
    </inertial>
    <visual>
      <origin rpy="0 0 0" xyz="0 0 0"/>
      <geometry>
        <mesh filename="../meshes/back_right_wheel_link.obj"/>
      </geometry>
      <material name="">
        <color rgba="0.1098 0.1098 0.1098 1"/>
      </material>
    </visual>
    <collision>
      <origin rpy="0 0 0" xyz="0 0 0"/>
      <geometry>
        <mesh filename="../meshes/back_right_wheel_link.obj"/>
      </geometry>
    </collision>
  </link>
  <joint name="back_right_wheel_joint" type="continuous">
    <origin rpy="-1.5708 0 3.1416" xyz="0.00015 -0.08725 0.0179"/>
    <parent link="base_link"/>
    <child link="/back_right_wheel_link"/>
    <axis xyz="0 0 -1"/>
  </joint>
  <!-- laser -->
  <link name="/base_laser_link"/>
  <joint name="laser_joint" type="fixed">
    <origin rpy="0 0 3.1416" xyz="0.11449 0 0.141"/>
    <parent link="base_link"/>
    <child link="/base_laser_link"/>
    <axis xyz="0 0 0"/>
  </joint>
  <!-- rgb camera -->
  <link name="/base_camera_link"/>
  <joint name="camera_joint" type="fixed">
    <origin rpy="0 0 0" xyz="0.15917 0.019164 0.073"/>
    <parent link="base_link"/>
    <child link="/base_camera_link"/>
    <axis xyz="0 0 0"/>
  </joint>
  <!-- imu -->
  <link name="/imu"/>
  <joint name="imu_joint" type="fixed">
    <origin rpy="0 0 0" xyz="0.0653 -0.0275 0.07671"/>
    <parent link="base_link"/>
    <child link="/imu"/>
    <axis xyz="0 0 0"/>
  </joint>
  <!-- ir camera -->
  <link name="/camera_link"/>
  <joint name="ir_camera_joint" type="fixed">
    <origin rpy="0 0 0" xyz="0.15917 0.039164 0.073"/>
    <parent link="base_link"/>
    <child link="/camera_link"/>
    <axis xyz="0 0 0"/>
  </joint>
</robot>

