<?xml version="1.0" encoding="utf-8"?>

<robot name="NanoCarPro" xmlns:xacro="http://ros.org/wiki/xacro">

  <xacro:arg name="robot_name" default=""/>
  <xacro:include filename="$(find nanocarpro_description)/urdf/nanocarpro_description.gazebo.xacro" /> 

  <link name="$(arg robot_name)/base_footprint"/>
  <joint name="base_joint" type="fixed">
    <parent link="$(arg robot_name)/base_footprint"/>
    <child link="$(arg robot_name)/base_link"/>
    <origin xyz="0.0 0.0 0.0157" rpy="0 0 0"/>
  </joint>

  <link
    name="$(arg robot_name)/base_link">
    <inertial>
      <origin
        xyz="0.072991 0.00046853 0.039966"
        rpy="0 0 0" />
      <mass
        value="0.45437" />
      <inertia
        ixx="0.00029844"
        ixy="-4.3951E-06"
        ixz="-2.191E-06"
        iyy="0.00043198"
        iyz="3.005E-07"
        izz="0.00068218" />
    </inertial>
    <visual>
      <origin
        xyz="0 0 0"
        rpy="0 0 0" />
      <geometry>
        <mesh
          filename="package://nanocarpro_description/meshes/base_link.STL" />
      </geometry>
      <material
        name="">
        <color
          rgba="1 1 1 1" />
      </material>
    </visual>
    <collision>
      <origin
        xyz="0 0 0"
        rpy="0 0 0" />
      <geometry>
        <mesh
          filename="package://nanocarpro_description/meshes/base_link.STL" />
      </geometry>
    </collision>
  </link>

  <!-- four wheel -->
  <xacro:macro name="wheel" params="prefix *joint_origin *joint_axis">
    <link
      name="$(arg robot_name)/${prefix}_wheel_link">
      <inertial>
        <origin
          xyz="-1.914E-05 -4.1633E-16 -0.0055056"
          rpy="0 0 0" />
        <mass
          value="0.056134" />
        <inertia
          ixx="2.4529E-05"
          ixy="1.012E-19"
          ixz="6.1905E-08"
          iyy="2.4528E-05"
          iyz="1.0409E-17"
          izz="4.2335E-05" />
      </inertial>
      <visual>
        <origin
          xyz="0 0 0"
          rpy="0 0 0" />
        <geometry>
          <mesh
            filename="package://nanocarpro_description/meshes/${prefix}_wheel_link.STL" />
        </geometry>
        <material
          name="">
          <color
            rgba="0.1098 0.1098 0.1098 1" />
        </material>
      </visual>
      <collision>
        <origin
          xyz="0 0 0"
          rpy="0 0 0" />
        <geometry>
          <mesh
            filename="package://nanocarpro_description/meshes/${prefix}_wheel_link.STL" />
        </geometry>
      </collision>
    </link>
    <joint
      name="${prefix}_wheel_joint"
      type="continuous">
      <xacro:insert_block name="joint_origin"/>
      <parent
        link="$(arg robot_name)/base_link" />
      <child
        link="$(arg robot_name)/${prefix}_wheel_link" />
      <xacro:insert_block name="joint_axis"/>
    </joint>
  </xacro:macro>
  <xacro:wheel prefix="front_left">
    <origin
      xyz="0.14338 0.08725 0.0179"
      rpy="-1.5708 0 0" />
    <axis
      xyz="0 0 1" />
  </xacro:wheel>
  <xacro:wheel prefix="front_right">
    <origin
      xyz="0.14338 -0.08725 0.0179"
      rpy="-1.5708 0 -3.1416" />
    <axis
      xyz="0 0 -1" />
  </xacro:wheel>
  <xacro:wheel prefix="back_left">
    <origin
      xyz="-0.00015 0.08725 0.0179"
      rpy="-1.5708 0 0" />
    <axis
      xyz="0 0 1" />
  </xacro:wheel>
  <xacro:wheel prefix="back_right">
    <origin
      xyz="0.00015 -0.08725 0.0179"
      rpy="-1.5708 0 3.1416" />
    <axis
      xyz="0 0 -1" />
  </xacro:wheel>

  <!-- laser -->
  <link name="$(arg robot_name)/base_laser_link"/>
  <joint
    name="laser_joint"
    type="fixed">
    <origin
      xyz="0.11449 0 0.141"
      rpy="0 0 3.1416" />
    <parent
      link="$(arg robot_name)/base_link" />
    <child
      link="$(arg robot_name)/base_laser_link" />
    <axis
      xyz="0 0 0" />
  </joint>

  <!-- rgb camera -->
  <link name="$(arg robot_name)/base_camera_link"/>
  <joint
    name="camera_joint"
    type="fixed">
    <origin
      xyz="0.15917 0.019164 0.073"
      rpy="0 0 0" />
    <parent
      link="$(arg robot_name)/base_link" />
    <child
      link="$(arg robot_name)/base_camera_link" />
    <axis
      xyz="0 0 0" />
  </joint>

  <!-- imu -->
  <link name="$(arg robot_name)/imu"/>
  <joint
    name="imu_joint"
    type="fixed">
    <origin
      xyz="0.0653 -0.0275 0.07671"
      rpy="0 0 0" />
    <parent
      link="$(arg robot_name)/base_link" />
    <child
      link="$(arg robot_name)/imu" />
    <axis
      xyz="0 0 0" />
  </joint>

  <!-- ir camera -->
  <link name="$(arg robot_name)/camera_link"/>
  <joint
    name="ir_camera_joint"
    type="fixed">
    <origin
      xyz="0.15917 0.039164 0.073"
      rpy="0 0 0" />
    <parent
      link="$(arg robot_name)/base_link" />
    <child
      link="$(arg robot_name)/camera_link" />
    <axis
      xyz="0 0 0" />
  </joint>

</robot>